<?xml version="1.0" encoding="utf-8"?>
<mujocoinclude>
	<body name="fp_surface" pos="0 -0.0110 0.02">
		<body pos="-0.0066667 0.0005 -0.01">
			<geom rgba="0 0.9 0 0.8" size="0.001566 0.0005 0.001566" type="ellipsoid"></geom>
			<body pos="0 0 0">
				<geom rgba="0 0.9 0 0.8" size="0.001566 0.0005 0.001566" type="ellipsoid" pos="0 -0.001 0" conaffinity="1" contype="2" mass="0.01"></geom>
				<joint axis="0 1 0" damping="18" limited="true" pos="0 0 0" range="-0.001 0.0001" stiffness="100" type="slide" user="1109"></joint>
				<site rgba="0.1 0.2 1 0.5" size="0.001566 0.0005 0.001566" type="box" name="fp1" pos="0 0 0"></site>
			</body>
		</body>
		<body pos="0.0 0.0005 -0.01">
			<geom rgba="0 0.9 0 0.8" size="0.001566 0.0005 0.001566" type="ellipsoid"></geom>
			<body pos="0 0 0">
				<geom rgba="0 0.9 0 0.8" size="0.001566 0.0005 0.001566" type="ellipsoid" pos="0 -0.001 0" conaffinity="1" contype="2" mass="0.01"></geom>
				<joint axis="0 1 0" damping="18" limited="true" pos="0 0 0" range="-0.001 0.0001" stiffness="100" type="slide" user="1109"></joint>
				<site rgba="0.1 0.2 1 0.5" size="0.001566 0.0005 0.001566" type="box" name="fp2" pos="0 0 0"></site>
			</body>
		</body>
		<body pos="0.0066667 0.0005 -0.01">
			<geom rgba="0 0.9 0 0.8" size="0.001566 0.0005 0.001566" type="ellipsoid"></geom>
			<body pos="0 0 0">
				<geom rgba="0 0.9 0 0.8" size="0.001566 0.0005 0.001566" type="ellipsoid" pos="0 -0.001 0" conaffinity="1" contype="2" mass="0.01"></geom>
				<joint axis="0 1 0" damping="18" limited="true" pos="0 0 0" range="-0.001 0.0001" stiffness="100" type="slide" user="1109"></joint>
				<site rgba="0.1 0.2 1 0.5" size="0.001566 0.0005 0.001566" type="box" name="fp3" pos="0 0 0"></site>
			</body>
		</body>
		<body pos="-0.0066667 0.0005 0.0">
			<geom rgba="0 0.9 0 0.8" size="0.001566 0.0005 0.001566" type="ellipsoid"></geom>
			<body pos="0 0 0">
				<geom rgba="0 0.9 0 0.8" size="0.001566 0.0005 0.001566" type="ellipsoid" pos="0 -0.001 0" conaffinity="1" contype="2" mass="0.01"></geom>
				<joint axis="0 1 0" damping="18" limited="true" pos="0 0 0" range="-0.001 0.0001" stiffness="100" type="slide" user="1109"></joint>
				<site rgba="0.1 0.2 1 0.5" size="0.001566 0.0005 0.001566" type="box" name="fp4" pos="0 0 0"></site>
			</body>
		</body>
		<body pos="0.0 0.0005 0.0">
			<geom rgba="0 0.9 0 0.8" size="0.001566 0.0005 0.001566" type="ellipsoid"></geom>
			<body pos="0 0 0">
				<geom rgba="0 0.9 0 0.8" size="0.001566 0.0005 0.001566" type="ellipsoid" pos="0 -0.001 0" conaffinity="1" contype="2" mass="0.01"></geom>
				<joint axis="0 1 0" damping="18" limited="true" pos="0 0 0" range="-0.001 0.0001" stiffness="100" type="slide" user="1109"></joint>
				<site rgba="0.1 0.2 1 0.5" size="0.001566 0.0005 0.001566" type="box" name="fp5" pos="0 0 0"></site>
			</body>
		</body>
		<body pos="0.0066667 0.0005 0.0">
			<geom rgba="0 0.9 0 0.8" size="0.001566 0.0005 0.001566" type="ellipsoid"></geom>
			<body pos="0 0 0">
				<geom rgba="0 0.9 0 0.8" size="0.001566 0.0005 0.001566" type="ellipsoid" pos="0 -0.001 0" conaffinity="1" contype="2" mass="0.01"></geom>
				<joint axis="0 1 0" damping="18" limited="true" pos="0 0 0" range="-0.001 0.0001" stiffness="100" type="slide" user="1109"></joint>
				<site rgba="0.1 0.2 1 0.5" size="0.001566 0.0005 0.001566" type="box" name="fp6" pos="0 0 0"></site>
			</body>
		</body>
		<body pos="-0.0066667 0.0005 0.01">
			<geom rgba="0 0.9 0 0.8" size="0.001566 0.0005 0.001566" type="ellipsoid"></geom>
			<body pos="0 0 0">
				<geom rgba="0 0.9 0 0.8" size="0.001566 0.0005 0.001566" type="ellipsoid" pos="0 -0.001 0" conaffinity="1" contype="2" mass="0.01"></geom>
				<joint axis="0 1 0" damping="18" limited="true" pos="0 0 0" range="-0.001 0.0001" stiffness="100" type="slide" user="1109"></joint>
				<site rgba="0.1 0.2 1 0.5" size="0.001566 0.0005 0.001566" type="box" name="fp7" pos="0 0 0"></site>
			</body>
		</body>
		<body pos="0.0 0.0005 0.01">
			<geom rgba="0 0.9 0 0.8" size="0.001566 0.0005 0.001566" type="ellipsoid"></geom>
			<body pos="0 0 0">
				<geom rgba="0 0.9 0 0.8" size="0.001566 0.0005 0.001566" type="ellipsoid" pos="0 -0.001 0" conaffinity="1" contype="2" mass="0.01"></geom>
				<joint axis="0 1 0" damping="18" limited="true" pos="0 0 0" range="-0.001 0.0001" stiffness="100" type="slide" user="1109"></joint>
				<site rgba="0.1 0.2 1 0.5" size="0.001566 0.0005 0.001566" type="box" name="fp8" pos="0 0 0"></site>
			</body>
		</body>
		<body pos="0.0066667 0.0005 0.01">
			<geom rgba="0 0.9 0 0.8" size="0.001566 0.0005 0.001566" type="ellipsoid"></geom>
			<body pos="0 0 0">
				<geom rgba="0 0.9 0 0.8" size="0.001566 0.0005 0.001566" type="ellipsoid" pos="0 -0.001 0" conaffinity="1" contype="2" mass="0.01"></geom>
				<joint axis="0 1 0" damping="18" limited="true" pos="0 0 0" range="-0.001 0.0001" stiffness="100" type="slide" user="1109"></joint>
				<site rgba="0.1 0.2 1 0.5" size="0.001566 0.0005 0.001566" type="box" name="fp9" pos="0 0 0"></site>
			</body>
		</body>
		<body pos="-0.0066667 0.0005 0.02">
			<geom rgba="0 0.9 0 0.8" size="0.001566 0.0005 0.001566" type="ellipsoid"></geom>
			<body pos="0 0 0">
				<geom rgba="0 0.9 0 0.8" size="0.001566 0.0005 0.001566" type="ellipsoid" pos="0 -0.001 0" conaffinity="1" contype="2" mass="0.01"></geom>
				<joint axis="0 1 0" damping="18" limited="true" pos="0 0 0" range="-0.001 0.0001" stiffness="100" type="slide" user="1109"></joint>
				<site rgba="0.1 0.2 1 0.5" size="0.001566 0.0005 0.001566" type="box" name="fp10" pos="0 0 0"></site>
			</body>
		</body>
		<body pos="0.0 0.0005 0.02">
			<geom rgba="0 0.9 0 0.8" size="0.001566 0.0005 0.001566" type="ellipsoid"></geom>
			<body pos="0 0 0">
				<geom rgba="0 0.9 0 0.8" size="0.001566 0.0005 0.001566" type="ellipsoid" pos="0 -0.001 0" conaffinity="1" contype="2" mass="0.01"></geom>
				<joint axis="0 1 0" damping="18" limited="true" pos="0 0 0" range="-0.001 0.0001" stiffness="100" type="slide" user="1109"></joint>
				<site rgba="0.1 0.2 1 0.5" size="0.001566 0.0005 0.001566" type="box" name="fp11" pos="0 0 0"></site>
			</body>
		</body>
		<body pos="0.0066667 0.0005 0.02">
			<geom rgba="0 0.9 0 0.8" size="0.001566 0.0005 0.001566" type="ellipsoid"></geom>
			<body pos="0 0 0">
				<geom rgba="0 0.9 0 0.8" size="0.001566 0.0005 0.001566" type="ellipsoid" pos="0 -0.001 0" conaffinity="1" contype="2" mass="0.01"></geom>
				<joint axis="0 1 0" damping="18" limited="true" pos="0 0 0" range="-0.001 0.0001" stiffness="100" type="slide" user="1109"></joint>
				<site rgba="0.1 0.2 1 0.5" size="0.001566 0.0005 0.001566" type="box" name="fp12" pos="0 0 0"></site>
			</body>
		</body>
	</body>
</mujocoinclude>