<mujocoinclude>
	<body name="fd_surface" pos="0 -0.007 0.0225">
			<body pos="-0.0066 0 0.005">
		            <geom rgba="0 .9 0 0.6" size="0.001366 0.0005 0.001366" type="ellipsoid"></geom>
		                    <body pos = "0 0 0">
		                            <geom  type="ellipsoid" pos ="0 -0.001 0" size="0.001566 0.0001 0.001566" rgba="0 1 0 0.2"/>
		                            <joint  type="slide" pos="0 0 0" axis="0 1 0" range="-.001 0.0001"   user="1109" stiffness = "100" damping = "18" limited= "true"/>
		                            <site name="fd_1" type="box" pos="0 -0.001 0" size="0.001366 0.004 0.001366" rgba="0 0 0 0.0"/>
		                    </body>
		    </body>
		    <body pos="0.0 0 0.005">
		            <geom rgba="0 .9 0 0.6" size="0.001366 0.0005 0.001366" type="ellipsoid"></geom>
		                    <body pos = "0 0 0">
		                            <geom  type="ellipsoid" pos ="0 -0.001 0" size="0.001566 0.0001 0.001566" rgba="0 1 0 0.2"/>
		                            <joint  type="slide" pos="0 0 0" axis="0 1 0" range="-.001 0.0001"   user="1109" stiffness = "100" damping = "18" limited= "true"/>
		                            <site name="fd_2" type="box" pos="0 -0.001 0" size="0.001366 0.004 0.001366" rgba="0 0 0 0.0"/>
		                    </body>
		    </body>
		    <body pos="0.0066 0 0.005">
		            <geom rgba="0 .9 0 0.6" size="0.001366 0.0005 0.001366" type="ellipsoid"></geom>
		                    <body pos = "0 0 0">
		                            <geom  type="ellipsoid" pos ="0 -0.001 0" size="0.001566 0.0001 0.001566" rgba="0 1 0 0.2"/>
		                            <joint  type="slide" pos="0 0 0" axis="0 1 0" range="-.001 0.0001"   user="1109" stiffness = "100" damping = "18" limited= "true"/>
		                            <site name="fd_3" type="box" pos="0 -0.001 0" size="0.001366 0.004 0.001366" rgba="0 0 0 0.0"/>
		                    </body>
		    </body>
		    <body pos="-0.0066 0 0.0">
		            <geom rgba="0 .9 0 0.6" size="0.001366 0.0005 0.001366" type="ellipsoid"></geom>
		                    <body pos = "0 0 0">
		                            <geom  type="ellipsoid" pos ="0 -0.001 0" size="0.001566 0.0001 0.001566" rgba="0 1 0 0.2"/>
		                            <joint  type="slide" pos="0 0 0" axis="0 1 0" range="-.001 0.0001"   user="1109" stiffness = "100" damping = "18" limited= "true"/>
		                            <site name="fd_4" type="box" pos="0 -0.001 0" size="0.001366 0.004 0.001366" rgba="0 0 0 0.0"/>
		                    </body>
		    </body>
		    <body pos="0.0 0 0.0">
		            <geom rgba="0 .9 0 0.6" size="0.001366 0.0005 0.001366" type="ellipsoid"></geom>
		                    <body pos = "0 0 0">
		                            <geom  type="ellipsoid" pos ="0 -0.001 0" size="0.001566 0.0001 0.001566" rgba="0 1 0 0.2"/>
		                            <joint  type="slide" pos="0 0 0" axis="0 1 0" range="-.001 0.0001"   user="1109" stiffness = "100" damping = "18" limited= "true"/>
		                            <site name="fd_5" type="box" pos="0 -0.001 0" size="0.001366 0.004 0.001366" rgba="0 0 0 0.0"/>
		                    </body>
		    </body>
		    <body pos="0.0066 0 0.0">
		            <geom rgba="0 .9 0 0.6" size="0.001366 0.0005 0.001366" type="ellipsoid"></geom>
		                    <body pos = "0 0 0">
		                            <geom  type="ellipsoid" pos ="0 -0.001 0" size="0.001566 0.0001 0.001566" rgba="0 1 0 0.2"/>
		                            <joint  type="slide" pos="0 0 0" axis="0 1 0" range="-.001 0.0001"   user="1109" stiffness = "100" damping = "18" limited= "true"/>
		                            <site name="fd_6" type="box" pos="0 -0.001 0" size="0.001366 0.004 0.001366" rgba="0 0 0 0.0"/>
		                    </body>
		    </body>
		    <body pos="-0.0066 0 -0.005">
		            <geom rgba="0 .9 0 0.6" size="0.001366 0.0005 0.001366" type="ellipsoid"></geom>
		                    <body pos = "0 0 0">
		                            <geom  type="ellipsoid" pos ="0 -0.001 0" size="0.001566 0.0001 0.001566" rgba="0 1 0 0.2"/>
		                            <joint  type="slide" pos="0 0 0" axis="0 1 0" range="-.001 0.0001"   user="1109" stiffness = "100" damping = "18" limited= "true"/>
		                            <site name="fd_7" type="box" pos="0 -0.001 0" size="0.001366 0.004 0.001366" rgba="0 0 0 0.0"/>
		                    </body>
		    </body>
		    <body pos="0.0 0 -0.005">
		            <geom rgba="0 .9 0 0.6" size="0.001366 0.0005 0.001366" type="ellipsoid"></geom>
		                    <body pos = "0 0 0">
		                            <geom  type="ellipsoid" pos ="0 -0.001 0" size="0.001566 0.0001 0.001566" rgba="0 1 0 0.2"/>
		                            <joint  type="slide" pos="0 0 0" axis="0 1 0" range="-.001 0.0001"   user="1109" stiffness = "100" damping = "18" limited= "true"/>
		                            <site name="fd_8" type="box" pos="0 -0.001 0" size="0.001366 0.004 0.001366" rgba="0 0 0 0.0"/>
		                    </body>
		    </body>
		    <body pos="0.0066 0 -0.005">
		            <geom rgba="0 .9 0 0.6" size="0.001366 0.0005 0.001366" type="ellipsoid"></geom>
		                    <body pos = "0 0 0">
		                            <geom  type="ellipsoid" pos ="0 -0.001 0" size="0.001566 0.0001 0.001566" rgba="0 1 0 0.2"/>
		                            <joint  type="slide" pos="0 0 0" axis="0 1 0" range="-.001 0.0001"   user="1109" stiffness = "100" damping = "18" limited= "true"/>
		                            <site name="fd_9" type="box" pos="0 -0.001 0" size="0.001366 0.004 0.001366" rgba="0 0 0 0.0"/>
		                    </body>
		    </body>
		    <body pos="-0.0066 0 -0.01">
		            <geom rgba="0 .9 0 0.6" size="0.001366 0.0005 0.001366" type="ellipsoid"></geom>
		                    <body pos = "0 0 0">
		                            <geom  type="ellipsoid" pos ="0 -0.001 0" size="0.001566 0.0001 0.001566" rgba="0 1 0 0.2"/>
		                            <joint  type="slide" pos="0 0 0" axis="0 1 0" range="-.001 0.0001"   user="1109" stiffness = "100" damping = "18" limited= "true"/>
		                            <site name="fd_10" type="box" pos="0 -0.001 0" size="0.001366 0.004 0.001366" rgba="0 0 0 0.0"/>
		                    </body>
		    </body>
		    <body pos="0.0 0 -0.01">
		            <geom rgba="0 .9 0 0.6" size="0.001366 0.0005 0.001366" type="ellipsoid"></geom>
		                    <body pos = "0 0 0">
		                            <geom  type="ellipsoid" pos ="0 -0.001 0" size="0.001566 0.0001 0.001566" rgba="0 1 0 0.2"/>
		                            <joint  type="slide" pos="0 0 0" axis="0 1 0" range="-.001 0.0001"   user="1109" stiffness = "100" damping = "18" limited= "true"/>
		                            <site name="fd_11" type="box" pos="0 -0.001 0" size="0.001366 0.004 0.001366" rgba="0 0 0 0.0"/>
		                    </body>
		    </body>
		    <body pos="0.0066 0 -0.01">
		            <geom rgba="0 .9 0 0.6" size="0.001366 0.0005 0.001366" type="ellipsoid"></geom>
		                    <body pos = "0 0 0">
		                            <geom  type="ellipsoid" pos ="0 -0.001 0" size="0.001566 0.0001 0.001566" rgba="0 1 0 0.2"/>
		                            <joint  type="slide" pos="0 0 0" axis="0 1 0" range="-.001 0.0001"   user="1109" stiffness = "100" damping = "18" limited= "true"/>
		                            <site name="fd_12" type="box" pos="0 -0.001 0" size="0.001366 0.004 0.001366" rgba="0 0 0 0.0"/>
		                    </body>
		    </body>
		</body>

</mujocoinclude>
