<mujocoinclude>
	<body name="mp_surface" pos="0 -0.009 0.0225">
	        	<body pos="-0.0066 0 0.02">
	                                <geom rgba="0 .9 0 0.6" size="0.001366 0.0005 0.001366" type="ellipsoid"></geom>
	                                        <body pos = "0 0 0">
	                                                <geom  type="ellipsoid" pos ="0 -0.001 0" size="0.001566 0.0001 0.001566" mass ="0.01" rgba=".5 .2 .5 0.8" contype = "2" conaffinity = "1"/>
	                                                <joint  type="slide" pos="0 0.00 0" axis="0 1 0" range="-.001 0.0001"  user="1109" stiffness = "100" damping ="18" limited = "true"/>
	                                                <site name="mp_1" type="box" pos ="0 -0.001 0" size="0.001366 0.0004 0.001366" rgba=".1 .2 1 0"/>
	                                        </body>
	                        </body>
	                        <body pos="0.0 0 0.02">
	                                <geom rgba="0 .9 0 0.6" size="0.001366 0.0005 0.001366" type="ellipsoid"></geom>
	                                        <body pos = "0 0 0">
	                                                <geom  type="ellipsoid" pos ="0 -0.001 0" size="0.001566 0.0001 0.001566" mass ="0.01" rgba=".5 .2 .5 0.8" contype = "2" conaffinity = "1"/>
	                                                <joint  type="slide" pos="0 0.00 0" axis="0 1 0" range="-.001 0.0001"  user="1109" stiffness = "100" damping ="18" limited = "true"/>
	                                                <site name="mp_2" type="box" pos ="0 -0.001 0" size="0.001366 0.0004 0.001366" rgba=".1 .2 1 0"/>
	                                        </body>
	                        </body>
	                        <body pos="0.0066 0 0.02">
	                                <geom rgba="0 .9 0 0.6" size="0.001366 0.0005 0.001366" type="ellipsoid"></geom>
	                                        <body pos = "0 0 0">
	                                                <geom  type="ellipsoid" pos ="0 -0.001 0" size="0.001566 0.0001 0.001566" mass ="0.01" rgba=".5 .2 .5 0.8" contype = "2" conaffinity = "1"/>
	                                                <joint  type="slide" pos="0 0.00 0" axis="0 1 0" range="-.001 0.0001"  user="1109" stiffness = "100" damping ="18" limited = "true"/>
	                                                <site name="mp_3" type="box" pos ="0 -0.001 0" size="0.001366 0.0004 0.001366" rgba=".1 .2 1 0"/>
	                                        </body>
	                        </body>
	                        <body pos="-0.0066 0 0.01">
	                                <geom rgba="0 .9 0 0.6" size="0.001366 0.0005 0.001366" type="ellipsoid"></geom>
	                                        <body pos = "0 0 0">
	                                                <geom  type="ellipsoid" pos ="0 -0.001 0" size="0.001566 0.0001 0.001566" mass ="0.01" rgba=".5 .2 .5 0.8" contype = "2" conaffinity = "1"/>
	                                                <joint  type="slide" pos="0 0.00 0" axis="0 1 0" range="-.001 0.0001"  user="1109" stiffness = "100" damping ="18" limited = "true"/>
	                                                <site name="mp_4" type="box" pos ="0 -0.001 0" size="0.001366 0.0004 0.001366" rgba=".1 .2 1 0"/>
	                                        </body>
	                        </body>
	                        <body pos="0.0 0 0.01">
	                                <geom rgba="0 .9 0 0.6" size="0.001366 0.0005 0.001366" type="ellipsoid"></geom>
	                                        <body pos = "0 0 0">
	                                                <geom  type="ellipsoid" pos ="0 -0.001 0" size="0.001566 0.0001 0.001566" mass ="0.01" rgba=".5 .2 .5 0.8" contype = "2" conaffinity = "1"/>
	                                                <joint  type="slide" pos="0 0.00 0" axis="0 1 0" range="-.001 0.0001"  user="1109" stiffness = "100" damping ="18" limited = "true"/>
	                                                <site name="mp_5" type="box" pos ="0 -0.001 0" size="0.001366 0.0004 0.001366" rgba=".1 .2 1 0"/>
	                                        </body>
	                        </body>
	                        <body pos="0.0066 0 0.01">
	                                <geom rgba="0 .9 0 0.6" size="0.001366 0.0005 0.001366" type="ellipsoid"></geom>
	                                        <body pos = "0 0 0">
	                                                <geom  type="ellipsoid" pos ="0 -0.001 0" size="0.001566 0.0001 0.001566" mass ="0.01" rgba=".5 .2 .5 0.8" contype = "2" conaffinity = "1"/>
	                                                <joint  type="slide" pos="0 0.00 0" axis="0 1 0" range="-.001 0.0001"  user="1109" stiffness = "100" damping ="18" limited = "true"/>
	                                                <site name="mp_6" type="box" pos ="0 -0.001 0" size="0.001366 0.0004 0.001366" rgba=".1 .2 1 0"/>
	                                        </body>
	                        </body>
	                        <body pos="-0.0066 0 0.0">
	                                <geom rgba="0 .9 0 0.6" size="0.001366 0.0005 0.001366" type="ellipsoid"></geom>
	                                        <body pos = "0 0 0">
	                                                <geom  type="ellipsoid" pos ="0 -0.001 0" size="0.001566 0.0001 0.001566" mass ="0.01" rgba=".5 .2 .5 0.8" contype = "2" conaffinity = "1"/>
	                                                <joint  type="slide" pos="0 0.00 0" axis="0 1 0" range="-.001 0.0001"  user="1109" stiffness = "100" damping ="18" limited = "true"/>
	                                                <site name="mp_7" type="box" pos ="0 -0.001 0" size="0.001366 0.0004 0.001366" rgba=".1 .2 1 0"/>
	                                        </body>
	                        </body>
	                        <body pos="0.0 0 0.0">
	                                <geom rgba="0 .9 0 0.6" size="0.001366 0.0005 0.001366" type="ellipsoid"></geom>
	                                        <body pos = "0 0 0">
	                                                <geom  type="ellipsoid" pos ="0 -0.001 0" size="0.001566 0.0001 0.001566" mass ="0.01" rgba=".5 .2 .5 0.8" contype = "2" conaffinity = "1"/>
	                                                <joint  type="slide" pos="0 0.00 0" axis="0 1 0" range="-.001 0.0001"  user="1109" stiffness = "100" damping ="18" limited = "true"/>
	                                                <site name="mp_8" type="box" pos ="0 -0.001 0" size="0.001366 0.0004 0.001366" rgba=".1 .2 1 0"/>
	                                        </body>
	                        </body>
	                        <body pos="0.0066 0 0.0">
	                                <geom rgba="0 .9 0 0.6" size="0.001366 0.0005 0.001366" type="ellipsoid"></geom>
	                                        <body pos = "0 0 0">
	                                                <geom  type="ellipsoid" pos ="0 -0.001 0" size="0.001566 0.0001 0.001566" mass ="0.01" rgba=".5 .2 .5 0.8" contype = "2" conaffinity = "1"/>
	                                                <joint  type="slide" pos="0 0.00 0" axis="0 1 0" range="-.001 0.0001"  user="1109" stiffness = "100" damping ="18" limited = "true"/>
	                                                <site name="mp_9" type="box" pos ="0 -0.001 0" size="0.001366 0.0004 0.001366" rgba=".1 .2 1 0"/>
	                                        </body>
	                        </body>
	                        <body pos="-0.0066 0 -0.01">
	                                <geom rgba="0 .9 0 0.6" size="0.001366 0.0005 0.001366" type="ellipsoid"></geom>
	                                        <body pos = "0 0 0">
	                                                <geom  type="ellipsoid" pos ="0 -0.001 0" size="0.001566 0.0001 0.001566" mass ="0.01" rgba=".5 .2 .5 0.8" contype = "2" conaffinity = "1"/>
	                                                <joint  type="slide" pos="0 0.00 0" axis="0 1 0" range="-.001 0.0001"  user="1109" stiffness = "100" damping ="18" limited = "true"/>
	                                                <site name="mp_10" type="box" pos ="0 -0.001 0" size="0.001366 0.0004 0.001366" rgba=".1 .2 1 0"/>
	                                        </body>
	                        </body>
	                        <body pos="0.0 0 -0.01">
	                                <geom rgba="0 .9 0 0.6" size="0.001366 0.0005 0.001366" type="ellipsoid"></geom>
	                                        <body pos = "0 0 0">
	                                                <geom  type="ellipsoid" pos ="0 -0.001 0" size="0.001566 0.0001 0.001566" mass ="0.01" rgba=".5 .2 .5 0.8" contype = "2" conaffinity = "1"/>
	                                                <joint  type="slide" pos="0 0.00 0" axis="0 1 0" range="-.001 0.0001"  user="1109" stiffness = "100" damping ="18" limited = "true"/>
	                                                <site name="mp_11" type="box" pos ="0 -0.001 0" size="0.001366 0.0004 0.001366" rgba=".1 .2 1 0"/>
	                                        </body>
	                        </body>
	                        <body pos="0.0066 0 -0.01">
	                                <geom rgba="0 .9 0 0.6" size="0.001366 0.0005 0.001366" type="ellipsoid"></geom>
	                                        <body pos = "0 0 0">
	                                                <geom  type="ellipsoid" pos ="0 -0.001 0" size="0.001566 0.0001 0.001566" mass ="0.01" rgba=".5 .2 .5 0.8" contype = "2" conaffinity = "1"/>
	                                                <joint  type="slide" pos="0 0.00 0" axis="0 1 0" range="-.001 0.0001"  user="1109" stiffness = "100" damping ="18" limited = "true"/>
	                                                <site name="mp_12" type="box" pos ="0 -0.001 0" size="0.001366 0.0004 0.001366" rgba=".1 .2 1 0"/>
	                                        </body>
	                        </body>



	        </body>


</mujocoinclude>
